2020-03-10 15:34:48,717 ERROR: Exception on /index [GET] [in d:\users\chris.garland\appdata\local\programs\python\python36\lib\site-packages\flask\app.py:1891]
Traceback (most recent call last):
  File "d:\users\chris.garland\appdata\local\programs\python\python36\lib\site-packages\flask\app.py", line 2446, in wsgi_app
    response = self.full_dispatch_request()
  File "d:\users\chris.garland\appdata\local\programs\python\python36\lib\site-packages\flask\app.py", line 1951, in full_dispatch_request
    rv = self.handle_user_exception(e)
  File "d:\users\chris.garland\appdata\local\programs\python\python36\lib\site-packages\flask\app.py", line 1820, in handle_user_exception
    reraise(exc_type, exc_value, tb)
  File "d:\users\chris.garland\appdata\local\programs\python\python36\lib\site-packages\flask\_compat.py", line 39, in reraise
    raise value
  File "d:\users\chris.garland\appdata\local\programs\python\python36\lib\site-packages\flask\app.py", line 1949, in full_dispatch_request
    rv = self.dispatch_request()
  File "d:\users\chris.garland\appdata\local\programs\python\python36\lib\site-packages\flask\app.py", line 1935, in dispatch_request
    return self.view_functions[rule.endpoint](**req.view_args)
  File "d:\users\chris.garland\appdata\local\programs\python\python36\lib\site-packages\flask_login\utils.py", line 272, in decorated_view
    return func(*args, **kwargs)
  File "D:\Users\chris.garland\Documents\Experimental\FlaskSB\app\routes.py", line 23, in index
    return render_template('index.html', title='Home', form=form, posts=posts)
  File "d:\users\chris.garland\appdata\local\programs\python\python36\lib\site-packages\flask\templating.py", line 138, in render_template
    ctx.app.jinja_env.get_or_select_template(template_name_or_list),
  File "D:\Users\chris.garland\AppData\Roaming\Python\Python36\site-packages\jinja2\environment.py", line 869, in get_or_select_template
    return self.get_template(template_name_or_list, parent, globals)
  File "D:\Users\chris.garland\AppData\Roaming\Python\Python36\site-packages\jinja2\environment.py", line 830, in get_template
    return self._load_template(name, self.make_globals(globals))
  File "D:\Users\chris.garland\AppData\Roaming\Python\Python36\site-packages\jinja2\environment.py", line 804, in _load_template
    template = self.loader.load(self, name, globals)
  File "D:\Users\chris.garland\AppData\Roaming\Python\Python36\site-packages\jinja2\loaders.py", line 125, in load
    code = environment.compile(source, name, filename)
  File "D:\Users\chris.garland\AppData\Roaming\Python\Python36\site-packages\jinja2\environment.py", line 591, in compile
    self.handle_exception(exc_info, source_hint=source_hint)
  File "D:\Users\chris.garland\AppData\Roaming\Python\Python36\site-packages\jinja2\environment.py", line 780, in handle_exception
    reraise(exc_type, exc_value, tb)
  File "D:\Users\chris.garland\AppData\Roaming\Python\Python36\site-packages\jinja2\_compat.py", line 37, in reraise
    raise value.with_traceback(tb)
  File "D:\Users\chris.garland\Documents\Experimental\FlaskSB\app\templates\index.html", line 21, in template
    {% endblock %}
  File "D:\Users\chris.garland\AppData\Roaming\Python\Python36\site-packages\jinja2\environment.py", line 497, in _parse
    return Parser(self, source, name, encode_filename(filename)).parse()
  File "D:\Users\chris.garland\AppData\Roaming\Python\Python36\site-packages\jinja2\parser.py", line 901, in parse
    result = nodes.Template(self.subparse(), lineno=1)
  File "D:\Users\chris.garland\AppData\Roaming\Python\Python36\site-packages\jinja2\parser.py", line 883, in subparse
    rv = self.parse_statement()
  File "D:\Users\chris.garland\AppData\Roaming\Python\Python36\site-packages\jinja2\parser.py", line 130, in parse_statement
    return getattr(self, 'parse_' + self.stream.current.value)()
  File "D:\Users\chris.garland\AppData\Roaming\Python\Python36\site-packages\jinja2\parser.py", line 268, in parse_block
    node.body = self.parse_statements(('name:endblock',), drop_needle=True)
  File "D:\Users\chris.garland\AppData\Roaming\Python\Python36\site-packages\jinja2\parser.py", line 165, in parse_statements
    result = self.subparse(end_tokens)
  File "D:\Users\chris.garland\AppData\Roaming\Python\Python36\site-packages\jinja2\parser.py", line 883, in subparse
    rv = self.parse_statement()
  File "D:\Users\chris.garland\AppData\Roaming\Python\Python36\site-packages\jinja2\parser.py", line 130, in parse_statement
    return getattr(self, 'parse_' + self.stream.current.value)()
  File "D:\Users\chris.garland\AppData\Roaming\Python\Python36\site-packages\jinja2\parser.py", line 213, in parse_if
    'name:endif'))
  File "D:\Users\chris.garland\AppData\Roaming\Python\Python36\site-packages\jinja2\parser.py", line 165, in parse_statements
    result = self.subparse(end_tokens)
  File "D:\Users\chris.garland\AppData\Roaming\Python\Python36\site-packages\jinja2\parser.py", line 883, in subparse
    rv = self.parse_statement()
  File "D:\Users\chris.garland\AppData\Roaming\Python\Python36\site-packages\jinja2\parser.py", line 144, in parse_statement
    self.fail_unknown_tag(token.value, token.lineno)
  File "D:\Users\chris.garland\AppData\Roaming\Python\Python36\site-packages\jinja2\parser.py", line 97, in fail_unknown_tag
    return self._fail_ut_eof(name, self._end_token_stack, lineno)
  File "D:\Users\chris.garland\AppData\Roaming\Python\Python36\site-packages\jinja2\parser.py", line 90, in _fail_ut_eof
    self.fail(' '.join(message), lineno)
  File "D:\Users\chris.garland\AppData\Roaming\Python\Python36\site-packages\jinja2\parser.py", line 59, in fail
    raise exc(msg, lineno, self.name, self.filename)
jinja2.exceptions.TemplateSyntaxError: Encountered unknown tag 'endblock'. You probably made a nesting mistake. Jinja is expecting this tag, but currently looking for 'elif' or 'else' or 'endif'. The innermost block that needs to be closed is 'if'.
2020-03-10 15:37:04,599 INFO: Microblog startup [in D:\Users\chris.garland\Documents\Experimental\FlaskSB\app\__init__.py:44]
2020-03-10 15:39:14,504 INFO: Microblog startup [in D:\Users\chris.garland\Documents\Experimental\FlaskSB\app\__init__.py:44]
2020-03-10 15:40:23,441 INFO: Microblog startup [in D:\Users\chris.garland\Documents\Experimental\FlaskSB\app\__init__.py:44]
2020-03-10 16:36:26,099 INFO: Microblog startup [in D:\Users\chris.garland\Documents\Experimental\FlaskSB\app\__init__.py:44]
2020-03-10 17:05:07,444 INFO: Microblog startup [in D:\Users\chris.garland\Documents\Experimental\FlaskSB\app\__init__.py:44]
2020-03-10 17:05:14,565 ERROR: Exception on /index [GET] [in d:\users\chris.garland\appdata\local\programs\python\python36\lib\site-packages\flask\app.py:1891]
Traceback (most recent call last):
  File "d:\users\chris.garland\appdata\local\programs\python\python36\lib\site-packages\flask\app.py", line 2446, in wsgi_app
    response = self.full_dispatch_request()
  File "d:\users\chris.garland\appdata\local\programs\python\python36\lib\site-packages\flask\app.py", line 1951, in full_dispatch_request
    rv = self.handle_user_exception(e)
  File "d:\users\chris.garland\appdata\local\programs\python\python36\lib\site-packages\flask\app.py", line 1820, in handle_user_exception
    reraise(exc_type, exc_value, tb)
  File "d:\users\chris.garland\appdata\local\programs\python\python36\lib\site-packages\flask\_compat.py", line 39, in reraise
    raise value
  File "d:\users\chris.garland\appdata\local\programs\python\python36\lib\site-packages\flask\app.py", line 1949, in full_dispatch_request
    rv = self.dispatch_request()
  File "d:\users\chris.garland\appdata\local\programs\python\python36\lib\site-packages\flask\app.py", line 1935, in dispatch_request
    return self.view_functions[rule.endpoint](**req.view_args)
  File "d:\users\chris.garland\appdata\local\programs\python\python36\lib\site-packages\flask_login\utils.py", line 272, in decorated_view
    return func(*args, **kwargs)
  File "D:\Users\chris.garland\Documents\Experimental\FlaskSB\app\routes.py", line 22, in index
    page = request.args.get('page', 1, type='int')
  File "d:\users\chris.garland\appdata\local\programs\python\python36\lib\site-packages\werkzeug\datastructures.py", line 319, in get
    rv = type(rv)
TypeError: 'str' object is not callable
2020-03-10 17:06:06,929 INFO: Microblog startup [in D:\Users\chris.garland\Documents\Experimental\FlaskSB\app\__init__.py:44]
2020-03-10 20:30:37,253 INFO: Microblog startup [in D:\Users\chris.garland\Documents\Experimental\FlaskSB\app\__init__.py:44]
