2020-03-05 16:53:48,746 ERROR: Exception on /user/Kristin [GET] [in d:\users\chris.garland\appdata\local\programs\python\python36\lib\site-packages\flask\app.py:1891]
Traceback (most recent call last):
  File "d:\users\chris.garland\appdata\local\programs\python\python36\lib\site-packages\sqlalchemy\engine\base.py", line 1246, in _execute_context
    cursor, statement, parameters, context
  File "d:\users\chris.garland\appdata\local\programs\python\python36\lib\site-packages\sqlalchemy\engine\default.py", line 588, in do_execute
    cursor.execute(statement, parameters)
sqlite3.OperationalError: no such table: followers

The above exception was the direct cause of the following exception:

Traceback (most recent call last):
  File "d:\users\chris.garland\appdata\local\programs\python\python36\lib\site-packages\flask\app.py", line 2446, in wsgi_app
    response = self.full_dispatch_request()
  File "d:\users\chris.garland\appdata\local\programs\python\python36\lib\site-packages\flask\app.py", line 1951, in full_dispatch_request
    rv = self.handle_user_exception(e)
  File "d:\users\chris.garland\appdata\local\programs\python\python36\lib\site-packages\flask\app.py", line 1820, in handle_user_exception
    reraise(exc_type, exc_value, tb)
  File "d:\users\chris.garland\appdata\local\programs\python\python36\lib\site-packages\flask\_compat.py", line 39, in reraise
    raise value
  File "d:\users\chris.garland\appdata\local\programs\python\python36\lib\site-packages\flask\app.py", line 1949, in full_dispatch_request
    rv = self.dispatch_request()
  File "d:\users\chris.garland\appdata\local\programs\python\python36\lib\site-packages\flask\app.py", line 1935, in dispatch_request
    return self.view_functions[rule.endpoint](**req.view_args)
  File "d:\users\chris.garland\appdata\local\programs\python\python36\lib\site-packages\flask_login\utils.py", line 272, in decorated_view
    return func(*args, **kwargs)
  File "D:\Users\chris.garland\Documents\Experimental\FlaskSB\app\routes.py", line 74, in user
    return render_template('user.html', user=user, posts=posts)
  File "d:\users\chris.garland\appdata\local\programs\python\python36\lib\site-packages\flask\templating.py", line 140, in render_template
    ctx.app,
  File "d:\users\chris.garland\appdata\local\programs\python\python36\lib\site-packages\flask\templating.py", line 120, in _render
    rv = template.render(context)
  File "D:\Users\chris.garland\AppData\Roaming\Python\Python36\site-packages\jinja2\asyncsupport.py", line 76, in render
    return original_render(self, *args, **kwargs)
  File "D:\Users\chris.garland\AppData\Roaming\Python\Python36\site-packages\jinja2\environment.py", line 1008, in render
    return self.environment.handle_exception(exc_info, True)
  File "D:\Users\chris.garland\AppData\Roaming\Python\Python36\site-packages\jinja2\environment.py", line 780, in handle_exception
    reraise(exc_type, exc_value, tb)
  File "D:\Users\chris.garland\AppData\Roaming\Python\Python36\site-packages\jinja2\_compat.py", line 37, in reraise
    raise value.with_traceback(tb)
  File "D:\Users\chris.garland\Documents\Experimental\FlaskSB\app\templates\user.html", line 1, in top-level template code
    {% extends 'base.html' %}
  File "D:\Users\chris.garland\Documents\Experimental\FlaskSB\app\templates\base.html", line 24, in top-level template code
    {% block content %}{% endblock %}
  File "D:\Users\chris.garland\Documents\Experimental\FlaskSB\app\templates\user.html", line 11, in block "content"
    <p>{{ user.followers.count() }} followers, {{ user.followed.count() }} following.</p>
  File "d:\users\chris.garland\appdata\local\programs\python\python36\lib\site-packages\sqlalchemy\orm\dynamic.py", line 335, in count
    return self._clone(sess).count()
  File "d:\users\chris.garland\appdata\local\programs\python\python36\lib\site-packages\sqlalchemy\orm\query.py", line 3653, in count
    return self.from_self(col).scalar()
  File "d:\users\chris.garland\appdata\local\programs\python\python36\lib\site-packages\sqlalchemy\orm\query.py", line 3377, in scalar
    ret = self.one()
  File "d:\users\chris.garland\appdata\local\programs\python\python36\lib\site-packages\sqlalchemy\orm\query.py", line 3347, in one
    ret = self.one_or_none()
  File "d:\users\chris.garland\appdata\local\programs\python\python36\lib\site-packages\sqlalchemy\orm\query.py", line 3316, in one_or_none
    ret = list(self)
  File "d:\users\chris.garland\appdata\local\programs\python\python36\lib\site-packages\sqlalchemy\orm\query.py", line 3389, in __iter__
    return self._execute_and_instances(context)
  File "d:\users\chris.garland\appdata\local\programs\python\python36\lib\site-packages\sqlalchemy\orm\query.py", line 3414, in _execute_and_instances
    result = conn.execute(querycontext.statement, self._params)
  File "d:\users\chris.garland\appdata\local\programs\python\python36\lib\site-packages\sqlalchemy\engine\base.py", line 982, in execute
    return meth(self, multiparams, params)
  File "d:\users\chris.garland\appdata\local\programs\python\python36\lib\site-packages\sqlalchemy\sql\elements.py", line 293, in _execute_on_connection
    return connection._execute_clauseelement(self, multiparams, params)
  File "d:\users\chris.garland\appdata\local\programs\python\python36\lib\site-packages\sqlalchemy\engine\base.py", line 1101, in _execute_clauseelement
    distilled_params,
  File "d:\users\chris.garland\appdata\local\programs\python\python36\lib\site-packages\sqlalchemy\engine\base.py", line 1250, in _execute_context
    e, statement, parameters, cursor, context
  File "d:\users\chris.garland\appdata\local\programs\python\python36\lib\site-packages\sqlalchemy\engine\base.py", line 1476, in _handle_dbapi_exception
    util.raise_from_cause(sqlalchemy_exception, exc_info)
  File "d:\users\chris.garland\appdata\local\programs\python\python36\lib\site-packages\sqlalchemy\util\compat.py", line 398, in raise_from_cause
    reraise(type(exception), exception, tb=exc_tb, cause=cause)
  File "d:\users\chris.garland\appdata\local\programs\python\python36\lib\site-packages\sqlalchemy\util\compat.py", line 152, in reraise
    raise value.with_traceback(tb)
  File "d:\users\chris.garland\appdata\local\programs\python\python36\lib\site-packages\sqlalchemy\engine\base.py", line 1246, in _execute_context
    cursor, statement, parameters, context
  File "d:\users\chris.garland\appdata\local\programs\python\python36\lib\site-packages\sqlalchemy\engine\default.py", line 588, in do_execute
    cursor.execute(statement, parameters)
sqlalchemy.exc.OperationalError: (sqlite3.OperationalError) no such table: followers
[SQL: SELECT count(*) AS count_1 
FROM (SELECT user.id AS user_id, user.username AS user_username, user.email AS user_email, user.password_hash AS user_password_hash, user.about_me AS user_about_me, user.last_seen AS user_last_seen 
FROM user, followers 
WHERE followers.followed_id = ? AND followers.follower_id = user.id) AS anon_1]
[parameters: (5,)]
(Background on this error at: http://sqlalche.me/e/e3q8)
2020-03-05 17:01:19,685 INFO: Microblog startup [in D:\Users\chris.garland\Documents\Experimental\FlaskSB\app\__init__.py:44]
2020-03-05 17:01:35,744 INFO: Microblog startup [in D:\Users\chris.garland\Documents\Experimental\FlaskSB\app\__init__.py:44]
2020-03-05 17:01:46,007 INFO: Microblog startup [in D:\Users\chris.garland\Documents\Experimental\FlaskSB\app\__init__.py:44]
2020-03-05 17:03:35,983 INFO: Microblog startup [in D:\Users\chris.garland\Documents\Experimental\FlaskSB\app\__init__.py:44]
2020-03-05 17:04:08,149 ERROR: Exception on /follow/Chris G [GET] [in d:\users\chris.garland\appdata\local\programs\python\python36\lib\site-packages\flask\app.py:1891]
Traceback (most recent call last):
  File "d:\users\chris.garland\appdata\local\programs\python\python36\lib\site-packages\flask\app.py", line 2446, in wsgi_app
    response = self.full_dispatch_request()
  File "d:\users\chris.garland\appdata\local\programs\python\python36\lib\site-packages\flask\app.py", line 1951, in full_dispatch_request
    rv = self.handle_user_exception(e)
  File "d:\users\chris.garland\appdata\local\programs\python\python36\lib\site-packages\flask\app.py", line 1820, in handle_user_exception
    reraise(exc_type, exc_value, tb)
  File "d:\users\chris.garland\appdata\local\programs\python\python36\lib\site-packages\flask\_compat.py", line 39, in reraise
    raise value
  File "d:\users\chris.garland\appdata\local\programs\python\python36\lib\site-packages\flask\app.py", line 1949, in full_dispatch_request
    rv = self.dispatch_request()
  File "d:\users\chris.garland\appdata\local\programs\python\python36\lib\site-packages\flask\app.py", line 1935, in dispatch_request
    return self.view_functions[rule.endpoint](**req.view_args)
  File "d:\users\chris.garland\appdata\local\programs\python\python36\lib\site-packages\flask_login\utils.py", line 272, in decorated_view
    return func(*args, **kwargs)
  File "D:\Users\chris.garland\Documents\Experimental\FlaskSB\app\routes.py", line 112, in follow
    return redirect(url_for('user', username))
TypeError: url_for() takes 1 positional argument but 2 were given
2020-03-05 17:06:08,294 INFO: Microblog startup [in D:\Users\chris.garland\Documents\Experimental\FlaskSB\app\__init__.py:44]
2020-03-05 17:08:57,919 INFO: Microblog startup [in D:\Users\chris.garland\Documents\Experimental\FlaskSB\app\__init__.py:44]
2020-03-05 17:10:00,890 INFO: Microblog startup [in D:\Users\chris.garland\Documents\Experimental\FlaskSB\app\__init__.py:44]
